Workbook

Sheet Grocery_Inventory_and_Sales_Dat
A1: Product_ID | B1: Product_Name | C1: Category | D1: Supplier_ID | E1: Supplier_Name | G1: Stock_Quantity | H1: Reorder_Level | I1: Reorder_Quantity | J1: Reorder_Required | K1: Recommended_Reorder_Quantity | L1: Priority_Reorders | M1: Unit_Price | N1: Inventory Value | O1: Date_Received | P1: Last_Order_Date | Q1: Expiration_Date | R1: Inventory Age | S1: Days Since Last Order | T1: Days Until Expiry | U1: Expiry Status | V1: Warehouse_Location | W1: Sales_Volume | X1: Total_Revenue_by_product | Y1: Inventory_Turnover_Rate | Z1: Status | AA1: Total Profit
A2: 29-205-1132 | B2: Sushi Rice | C2: Grains & Pulses | D2: 38-037-1699 | E2: Jaxnation | F2: =SUM(G2:G991) -> 55053 | G2: 22 | H2: 72 | I2: 70 | J2: Require | K2: 72 | L2: High Priority | M2: 4.5 | N2: =G2*M2 -> 99 | O2: 45520 | P2: 45472 | Q2: 45554 | R2: 559 | S2: 607 | T2: 525 | U2: =IF(T2<0,"Expired",IF(T2<=550,"Expiring Soon","Safe")) -> Expiring Soon | V2: 48 Del Sol Trail | W2: 32 | X2: =W2*N2 -> 3168 | Y2: 19 | Z2: Discontinued | AA2: =X2-Grocery_Inventory_and_Sales_Dat!N2 -> 3069
A3: 40-681-9981 | B3: Arabica Coffee | C3: Beverages | D3: 54-470-2479 | E3: Feedmix | F3: =AVERAGE(M2:M991) -> 5.9241919 | G3: 45 | H3: 77 | I3: 2 | J3: Require | K3: 77 | L3: High Priority | M3: 20 | N3: =G3*M3 -> 900 | O3: 45302 | P3: 45441 | Q3: 45420 | R3: 777 | S3: 638 | T3: 659 | U3: =IF(T3<0,"Expired",IF(T3<=550,"Expiring Soon","Safe")) -> Safe | V3: 36 3rd Place | W3: 85 | X3: =W3*N3 -> 76500 | Y3: 1 | Z3: Discontinued | AA3: =X3-Grocery_Inventory_and_Sales_Dat!N3 -> 75600
A4: 06-955-3428 | B4: Black Rice | C4: Grains & Pulses | D4: 54-031-2945 | E4: Vinder | F4: =SUM(W2:W991) -> 58336 | G4: 30 | H4: 38 | I4: 83 | J4: Require | K4: 38 | L4: Normal | M4: 6 | N4: =G4*M4 -> 180 | O4: 45359 | P4: 45571 | Q4: 45557 | R4: 720 | S4: 508 | T4: 522 | U4: =IF(T4<0,"Expired",IF(T4<=550,"Expiring Soon","Safe")) -> Expiring Soon | V4: 3296 Walton Court | W4: 31 | X4: =W4*N4 -> 5580 | Y4: 34 | Z4: Backordered | AA4: =X4-Grocery_Inventory_and_Sales_Dat!N4 -> 5400
A5: 71-594-6552 | B5: Long Grain Rice | C5: Grains & Pulses | D5: 63-492-7603 | E5: Brightbean | G5: 12 | H5: 59 | I5: 62 | J5: Require | K5: 59 | L5: Normal | M5: 1.5 | N5: =G5*M5 -> 18 | O5: 45516 | P5: 45707 | Q5: 45399 | R5: 563 | S5: 372 | T5: 680 | U5: =IF(T5<0,"Expired",IF(T5<=550,"Expiring Soon","Safe")) -> Safe | V5: 3 Westerfield Crossing | W5: 95 | X5: =W5*N5 -> 1710 | Y5: 99 | Z5: Active | AA5: =X5-Grocery_Inventory_and_Sales_Dat!N5 -> 1692
A6: 57-437-1828 | B6: Plum | C6: Fruits & Vegetables | D6: 54-226-4308 | E6: Topicstorm | G6: 37 | H6: 30 | I6: 74 | J6: Sufficient | K6: 0 | L6: Normal | M6: 4 | N6: =G6*M6 -> 148 | O6: 45358 | P6: 45606 | Q6: 45570 | R6: 721 | S6: 473 | T6: 509 | U6: =IF(T6<0,"Expired",IF(T6<=550,"Expiring Soon","Safe")) -> Expiring Soon | V6: 15068 Scoville Court | W6: 62 | X6: =W6*N6 -> 9176 | Y6: 25 | Z6: Backordered | AA6: =X6-Grocery_Inventory_and_Sales_Dat!N6 -> 9028
A7: 21-120-6238 | B7: All-Purpose Flour | C7: Grains & Pulses | D7: 86-292-4587 | E7: Dabjam | G7: 55 | H7: 33 | I7: 14 | J7: Sufficient | K7: 0 | L7: Normal | M7: 1.75 | N7: =G7*M7 -> 96.25 | O7: 45363 | P7: 45438 | Q7: 45540 | R7: 716 | S7: 641 | T7: 539 | U7: =IF(T7<0,"Expired",IF(T7<=550,"Expiring Soon","Safe")) -> Expiring Soon | V7: 050 Mcbride Avenue | W7: 34 | X7: =W7*N7 -> 3272.5 | Y7: 62 | Z7: Discontinued | AA7: =X7-Grocery_Inventory_and_Sales_Dat!N7 -> 3176.25
A8: 71-516-1996 | B8: Corn Oil | C8: Oils & Fats | D8: 04-391-7610 | E8: Tagfeed | G8: 96 | H8: 52 | I8: 16 | J8: Sufficient | K8: 0 | L8: Normal | M8: 2.5 | N8: =G8*M8 -> 240 | O8: 45369 | P8: 45478 | Q8: 45463 | R8: 710 | S8: 601 | T8: 616 | U8: =IF(T8<0,"Expired",IF(T8<=550,"Expiring Soon","Safe")) -> Safe | V8: 12 Truax Court | W8: 67 | X8: =W8*N8 -> 16080 | Y8: 13 | Z8: Active | AA8: =X8-Grocery_Inventory_and_Sales_Dat!N8 -> 15840
A9: 39-629-5554 | B9: Egg (Goose) | C9: Dairy | D9: 67-679-4930 | E9: Muxo | G9: 44 | H9: 90 | I9: 17 | J9: Require | K9: 90 | L9: High Priority | M9: 2.5 | N9: =G9*M9 -> 110 | O9: 45718 | P9: 45539 | Q9: 45693 | R9: 361 | S9: 540 | T9: 386 | U9: =IF(T9<0,"Expired",IF(T9<=550,"Expiring Soon","Safe")) -> Expiring Soon | V9: 267 International Plaza | W9: 21 | X9: =W9*N9 -> 2310 | Y9: 91 | Z9: Discontinued | AA9: =X9-Grocery_Inventory_and_Sales_Dat!N9 -> 2200
A10: 66-268-8345 | B10: Greek Yogurt | C10: Dairy | D10: 32-182-1895 | E10: Thoughtstorm | G10: 91 | H10: 84 | I10: 11 | J10: Sufficient | K10: 0 | L10: Normal | M10: 3 | N10: =G10*M10 -> 273 | O10: 45394 | P10: 45328 | Q10: 45665 | R10: 685 | S10: 751 | T10: 414 | U10: =IF(T10<0,"Expired",IF(T10<=550,"Expiring Soon","Safe")) -> Expiring Soon | V10: 550 Clemons Plaza | W10: 56 | X10: =W10*N10 -> 15288 | Y10: 90 | Z10: Active | AA10: =X10-Grocery_Inventory_and_Sales_Dat!N10 -> 15015
A11: 46-452-9419 | B11: Egg (Duck) | C11: Dairy | D11: 67-137-4215 | E11: Wordify | G11: 43 | H11: 10 | I11: 15 | J11: Sufficient | K11: 0 | L11: Normal | M11: 1 | N11: =G11*M11 -> 43 | O11: 45614 | P11: 45610 | Q11: 45481 | R11: 465 | S11: 469 | T11: 598 | U11: =IF(T11<0,"Expired",IF(T11<=550,"Expiring Soon","Safe")) -> Safe | V11: 55782 Welch Hill | W11: 27 | X11: =W11*N11 -> 1161 | Y11: 69 | Z11: Active | AA11: =X11-Grocery_Inventory_and_Sales_Dat!N11 -> 1118
A12: 51-469-4611 | B12: Long Grain Rice | C12: Grains & Pulses | D12: 62-029-0827 | E12: Fivebridge | G12: 62 | H12: 81 | I12: 91 | J12: Require | K12: 81 | L12: High Priority | M12: 1.6 | N12: =G12*M12 -> 99.2 | O12: 45644 | P12: 45436 | Q12: 45664 | R12: 435 | S12: 643 | T12: 415 | U12: =IF(T12<0,"Expired",IF(T12<=550,"Expiring Soon","Safe")) -> Expiring Soon | V12: 04776 Saint Paul Park | W12: 100 | X12: =W12*N12 -> 9920 | Y12: 42 | Z12: Discontinued | AA12: =X12-Grocery_Inventory_and_Sales_Dat!N12 -> 9820.8
A13: 42-220-9305 | B13: White Sugar | C13: Grains & Pulses | D13: 56-092-7992 | E13: Zooxo | G13: 91 | H13: 98 | I13: 6 | J13: Require | K13: 98 | L13: High Priority | M13: 2 | N13: =G13*M13 -> 182 | O13: 45584 | P13: 45608 | Q13: 45579 | R13: 495 | S13: 471 | T13: 500 | U13: =IF(T13<0,"Expired",IF(T13<=550,"Expiring Soon","Safe")) -> Expiring Soon | V13: 61932 Cascade Crossing | W13: 100 | X13: =W13*N13 -> 18200 | Y13: 20 | Z13: Backordered | AA13: =X13-Grocery_Inventory_and_Sales_Dat!N13 -> 18018
A14: 75-094-1179 | B14: Rye Bread | C14: Bakery | D14: 57-615-0729 | E14: Vitz | G14: 26 | H14: 79 | I14: 31 | J14: Require | K14: 79 | L14: High Priority | M14: 3 | N14: =G14*M14 -> 78 | O14: 45639 | P14: 45902 | Q14: 45491 | R14: 440 | S14: 177 | T14: 588 | U14: =IF(T14<0,"Expired",IF(T14<=550,"Expiring Soon","Safe")) -> Safe | V14: 13 Forest Run Place | W14: 47 | X14: =W14*N14 -> 3666 | Y14: 41 | Z14: Discontinued | AA14: =X14-Grocery_Inventory_and_Sales_Dat!N14 -> 3588
A15: 11-073-0189 | B15: Plum | C15: Fruits & Vegetables | D15: 75-190-3627 | E15: Voomm | G15: 95 | H15: 50 | I15: 76 | J15: Sufficient | K15: 0 | L15: Normal | M15: 4 | N15: =G15*M15 -> 380 | O15: 45416 | P15: 45556 | Q15: 45418 | R15: 663 | S15: 523 | T15: 661 | U15: =IF(T15<0,"Expired",IF(T15<=550,"Expiring Soon","Safe")) -> Safe | V15: 5104 Jana Court | W15: 69 | X15: =W15*N15 -> 26220 | Y15: 5 | Z15: Active | AA15: =X15-Grocery_Inventory_and_Sales_Dat!N15 -> 25840
A16: 22-621-2774 | B16: Strawberries | C16: Fruits & Vegetables | D16: 70-901-6191 | E16: Babblestorm | G16: 54 | H16: 26 | I16: 16 | J16: Sufficient | K16: 0 | L16: Normal | M16: 6 | N16: =G16*M16 -> 324 | O16: 45599 | P16: 45473 | Q16: 45457 | R16: 480 | S16: 606 | T16: 622 | U16: =IF(T16<0,"Expired",IF(T16<=550,"Expiring Soon","Safe")) -> Safe | V16: 00 Drewry Court | W16: 63 | X16: =W16*N16 -> 20412 | Y16: 97 | Z16: Active | AA16: =X16-Grocery_Inventory_and_Sales_Dat!N16 -> 20088
... A686: 84-151-2114 | B686: Brown Rice | C686: Grains & Pulses | D686: 79-704-1471 | E686: Avamm | G686: 39 | H686: 57 | I686: 54 | J686: Require | K686: 57 | L686: Normal | M686: 2.5 | N686: =G686*M686 -> 97.5 | O686: 45455 | P686: 45446 | Q686: 45515 | R686: 624 | S686: 633 | T686: 564 | U686: =IF(T686<0,"Expired",IF(T686<=550,"Expiring Soon","Safe")) -> Safe | V686: 12 Rigney Street | W686: 77 | X686: =W686*N686 -> 7507.5 | Y686: 32 | Z686: Active | AA686: =X686-Grocery_Inventory_and_Sales_Dat!N686 -> 7410
A687: 10-378-9729 | B687: Cabbage | D687: 83-941-9620 | E687: Rooxo | G687: 69 | H687: 21 | I687: 68 | J687: Sufficient | K687: 0 | L687: Normal | M687: 66.55 | N687: =G687*M687 -> 4591.95 | O687: 45649 | P687: 45622 | Q687: 45556 | R687: 430 | S687: 457 | T687: 523 | U687: =IF(T687<0,"Expired",IF(T687<=550,"Expiring Soon","Safe")) -> Expiring Soon | V687: 2 Butterfield Pass | W687: 36 | X687: =W687*N687 -> 165310.2 | Y687: 35 | Z687: Discontinued | AA687: =X687-Grocery_Inventory_and_Sales_Dat!N687 -> 160718.25
A688: 53-930-2215 | B688: Egg (Goose) | C688: Dairy | D688: 42-210-6541 | E688: Gabvine | G688: 60 | H688: 43 | I688: 32 | J688: Sufficient | K688: 0 | L688: Normal | M688: 2.5 | N688: =G688*M688 -> 150 | O688: 45419 | P688: 45392 | Q688: 45482 | R688: 660 | S688: 687 | T688: 597 | U688: =IF(T688<0,"Expired",IF(T688<=550,"Expiring Soon","Safe")) -> Safe | V688: 292 Utah Street | W688: 77 | X688: =W688*N688 -> 11550 | Y688: 60 | Z688: Active | AA688: =X688-Grocery_Inventory_and_Sales_Dat!N688 -> 11400
A689: 02-034-6209 | B689: Sour Cream | C689: Dairy | D689: 34-724-1913 | E689: Yodel | G689: 22 | H689: 43 | I689: 3 | J689: Require | K689: 43 | L689: Normal | M689: 4.1 | N689: =G689*M689 -> 90.2 | O689: 45659 | P689: 45499 | Q689: 45573 | R689: 420 | S689: 580 | T689: 506 | U689: =IF(T689<0,"Expired",IF(T689<=550,"Expiring Soon","Safe")) -> Expiring Soon | V689: 96 Brown Drive | W689: 45 | X689: =W689*N689 -> 4059 | Y689: 87 | Z689: Backordered | AA689: =X689-Grocery_Inventory_and_Sales_Dat!N689 -> 3968.8
A690: 28-003-8065 | B690: Almond Flour | C690: Grains & Pulses | D690: 42-579-7177 | E690: Voonte | G690: 79 | H690: 47 | I690: 51 | J690: Sufficient | K690: 0 | L690: Normal | M690: 9.5 | N690: =G690*M690 -> 750.5 | O690: 45492 | P690: 45704 | Q690: 45685 | R690: 587 | S690: 375 | T690: 394 | U690: =IF(T690<0,"Expired",IF(T690<=550,"Expiring Soon","Safe")) -> Expiring Soon | V690: 65 Merry Circle | W690: 83 | X690: =W690*N690 -> 62291.5 | Y690: 69 | Z690: Discontinued | AA690: =X690-Grocery_Inventory_and_Sales_Dat!N690 -> 61541
A691: 19-021-5024 | B691: Broccoli | C691: Fruits & Vegetables | D691: 75-369-5047 | E691: Rhyzio | G691: 47 | H691: 63 | I691: 86 | J691: Require | K691: 63 | L691: High Priority | M691: 4 | N691: =G691*M691 -> 188 | O691: 45431 | P691: 45701 | Q691: 45419 | R691: 648 | S691: 378 | T691: 660 | U691: =IF(T691<0,"Expired",IF(T691<=550,"Expiring Soon","Safe")) -> Safe | V691: 4 Heffernan Lane | W691: 76 | X691: =W691*N691 -> 14288 | Y691: 29 | Z691: Active | AA691: =X691-Grocery_Inventory_and_Sales_Dat!N691 -> 14100
A692: 07-846-4804 | B692: Jasmine Rice | C692: Grains & Pulses | D692: 30-605-2164 | E692: Tagcat | G692: 20 | H692: 25 | I692: 73 | J692: Require | K692: 25 | L692: Normal | M692: 4.75 | N692: =G692*M692 -> 95 | O692: 45514 | P692: 45329 | Q692: 45560 | R692: 565 | S692: 750 | T692: 519 | U692: =IF(T692<0,"Expired",IF(T692<=550,"Expiring Soon","Safe")) -> Expiring Soon | V692: 2 Fair Oaks Pass | W692: 78 | X692: =W692*N692 -> 7410 | Y692: 1 | Z692: Discontinued | AA692: =X692-Grocery_Inventory_and_Sales_Dat!N692 -> 7315
A693: 70-542-4269 | B693: Gouda Cheese | C693: Dairy | D693: 27-772-7906 | E693: Gigazoom | G693: 41 | H693: 22 | I693: 11 | J693: Sufficient | K693: 0 | L693: Normal | M693: 7 | N693: =G693*M693 -> 287 | O693: 45462 | P693: 45405 | Q693: 45399 | R693: 617 | S693: 674 | T693: 680 | U693: =IF(T693<0,"Expired",IF(T693<=550,"Expiring Soon","Safe")) -> Safe | V693: 7 Victoria Hill | W693: 86 | X693: =W693*N693 -> 24682 | Y693: 30 | Z693: Active | AA693: =X693-Grocery_Inventory_and_Sales_Dat!N693 -> 24395
A694: 52-797-6961 | B694: Tilapia | C694: Seafood | D694: 75-793-8978 | E694: Plajo | G694: 46 | H694: 80 | I694: 88 | J694: Require | K694: 80 | L694: High Priority | M694: 7 | N694: =G694*M694 -> 322 | O694: 45554 | P694: 45479 | Q694: 45460 | R694: 525 | S694: 600 | T694: 619 | U694: =IF(T694<0,"Expired",IF(T694<=550,"Expiring Soon","Safe")) -> Safe | V694: 13799 Quincy Park | W694: 62 | X694: =W694*N694 -> 19964 | Y694: 22 | Z694: Discontinued | AA694: =X694-Grocery_Inventory_and_Sales_Dat!N694 -> 19642
A695: 66-327-2821 | B695: Palm Oil | C695: Oils & Fats | D695: 82-525-7224 | E695: Skipstorm | G695: 67 | H695: 57 | I695: 36 | J695: Sufficient | K695: 0 | L695: Normal | M695: 1.8 | N695: =G695*M695 -> 120.6 | O695: 45330 | P695: 45569 | Q695: 45439 | R695: 749 | S695: 510 | T695: 640 | U695: =IF(T695<0,"Expired",IF(T695<=550,"Expiring Soon","Safe")) -> Safe | V695: 703 Hermina Center | W695: 78 | X695: =W695*N695 -> 9406.8 | Y695: 60 | Z695: Active | AA695: =X695-Grocery_Inventory_and_Sales_Dat!N695 -> 9286.2
A696: 12-093-9863 | B696: Arborio Rice | C696: Grains & Pulses | D696: 21-416-3796 | E696: Feednation | G696: 51 | H696: 19 | I696: 96 | J696: Sufficient | K696: 0 | L696: Normal | M696: 4.5 | N696: =G696*M696 -> 229.5 | O696: 45619 | P696: 45902 | Q696: 45469 | R696: 460 | S696: 177 | T696: 610 | U696: =IF(T696<0,"Expired",IF(T696<=550,"Expiring Soon","Safe")) -> Safe | V696: 6748 Mitchell Road | W696: 73 | X696: =W696*N696 -> 16753.5 | Y696: 42 | Z696: Active | AA696: =X696-Grocery_Inventory_and_Sales_Dat!N696 -> 16524
A697: 08-396-2704 | B697: White Sugar | C697: Grains & Pulses | D697: 94-186-9620 | E697: Cogibox | G697: 42 | H697: 12 | I697: 28 | J697: Sufficient | K697: 0 | L697: Normal | M697: 2 | N697: =G697*M697 -> 84 | O697: 45568 | P697: 45295 | Q697: 45422 | R697: 511 | S697: 784 | T697: 657 | U697: =IF(T697<0,"Expired",IF(T697<=550,"Expiring Soon","Safe")) -> Safe | V697: 160 Crowley Center | W697: 80 | X697: =W697*N697 -> 6720 | Y697: 8 | Z697: Discontinued | AA697: =X697-Grocery_Inventory_and_Sales_Dat!N697 -> 6636
A698: 72-970-0239 | B698: Sesame Oil | C698: Oils & Fats | D698: 64-752-3122 | E698: Divanoodle | G698: 85 | H698: 86 | I698: 21 | J698: Require | K698: 86 | L698: High Priority | M698: 6.5 | N698: =G698*M698 -> 552.5 | O698: 45473 | P698: 45497 | Q698: 45491 | R698: 606 | S698: 582 | T698: 588 | U698: =IF(T698<0,"Expired",IF(T698<=550,"Expiring Soon","Safe")) -> Safe | V698: 73966 Pond Trail | W698: 78 | X698: =W698*N698 -> 43095 | Y698: 53 | Z698: Backordered | AA698: =X698-Grocery_Inventory_and_Sales_Dat!N698 -> 42542.5
A699: 03-940-0630 | B699: Sunflower Oil | C699: Oils & Fats | D699: 49-762-8263 | E699: Skibox | G699: 23 | H699: 43 | I699: 75 | J699: Require | K699: 43 | L699: Normal | M699: 2.5 | N699: =G699*M699 -> 57.5 | O699: 45515 | P699: 45596 | Q699: 45385 | R699: 564 | S699: 483 | T699: 694 | U699: =IF(T699<0,"Expired",IF(T699<=550,"Expiring Soon","Safe")) -> Safe | V699: 27408 Burning Wood Street | W699: 91 | X699: =W699*N699 -> 5232.5 | Y699: 86 | Z699: Discontinued | AA699: =X699-Grocery_Inventory_and_Sales_Dat!N699 -> 5175
... A991: 28-044-4102 | B991: Papaya | C991: Fruits & Vegetables | D991: 93-358-1118 | E991: Yakijo | G991: 19 | H991: 28 | I991: 83 | J991: Require | K991: 28 | L991: Normal | M991: 4.5 | N991: =G991*M991 -> 85.5 | O991: 45622 | P991: 45294 | Q991: 45531 | R991: 457 | S991: 785 | T991: 548 | U991: =IF(T991<0,"Expired",IF(T991<=550,"Expiring Soon","Safe")) -> Expiring Soon | V991: 309 Burning Wood Center | W991: 91 | X991: =W991*N991 -> 7780.5 | Y991: 73 | Z991: Discontinued | AA991: =X991-Grocery_Inventory_and_Sales_Dat!N991 -> 7695
A997: Inventory Risk Calculation | B997: Inventory Risk % | C997: Risk_status
A998: =SUMIF(U2:U991,"Expiring Soon",N2:N991) -> 164236.76 | B998: =A998/SUM(N2:N991) -> 0.49371542 | C998: =IF(B998>30%,"High Risk","LowRisk") -> High Risk
A1001: Reorder Financial Impact Analysis | B1001: Percentage Of Capital In Reorder-required items
A1002: =SUMIF(J2:J991,"Require",N2:N991) -> 103132.74 | B1002: =A1002/SUM(N2:N991) -> 0.3100294
A1007: Total Profit Margin
A1008: Total Profit | B1008: Total Revenue | C1008: Total Profit Margin
A1009: =SUM(AA:AA) -> 19469042 | B1009: =SUM(X:X) -> 19801696 | C1009: =A1009/B1009 -> 0.9832007

Sheet EDA
A1: EDA Exploratory Data Analysis
A3: Column1 | B3: Column2
A4: DataSet Summary
A5: Total Products | B5: 990
A6: Total Categories | B6: 6
A7: Total Suppliers | B7: 349
A8: Total Stock Quantity | B8: 55053
A9: Average Unit Price | B9: 5.92
A10: Total Sales Volume | B10: 58336
A13: 1. Product Distribution by Category
A15: Row Labels | B15: Count of Product_ID
A16: Bakery | B16: 74
A17: Beverages | B17: 75
A18: Dairy | B18: 180
A19: Fruits & Vegetables | B19: 331
A20: Grains & Pulses | B20: 162
A21: Oils & Fats | B21: 77
A22: Seafood | B22: 90
A23: (blank) | B23: 1
A24: Grand Total | B24: 990
A31: 2. Supplier Contribution
A32: Row Labels | B32: Count of Product_ID
A33: Abata | B33: 3
A34: Abatz | B34: 3
A35: Agivu | B35: 1
A36: Aibox | B36: 3
A37: Aimbu | B37: 1
A38: Ainyx | B38: 3
A39: Aivee | B39: 3
A40: Avamba | B40: 2
A41: Avamm | B41: 2
A42: Avavee | B42: 2
A43: Avaveo | B43: 5
A44: Babbleblab | B44: 1
... A383: Grand Total | B383: 990
A386: 3. Stock Quantity Distribution
A387: Row Labels | B387: Sum of Stock_Quantity
A388: All-Purpose Flour | B388: 159
A389: Almond Flour | B389: 582
A390: Anchovies | B390: 816
...

Sheet Graphical Representations
A1: Inventory Distribution
A3: Row Labels | B3: Sum of Inventory Value
A4: Bakery | B4: 16788.8
A5: Beverages | B5: 62942.25
A6: Dairy | B6: 50601.95
A7: Fruits & Vegetables | B7: 86033.16
A8: Grains & Pulses | B8: 31969.2
A9: Oils & Fats | B9: 17211.5
A10: Seafood | B10: 62515.9
A11: (blank) | B11: 4591.95
A12: Grand Total | B12: 332654.71
A24: Row Labels | B24: Sum of Total_Revenue_by_product
A25: Bakery | B25: 1021551.6
A26: Beverages | B26: 3848843.9
A27: Dairy | B27: 3099638.8
A28: Fruits & Vegetables | B28: 5101257.6
A29: Grains & Pulses | B29: 1699582.6
A30: Oils & Fats | B30: 1042268.8
A31: Seafood | B31: 3823243
A32: (blank) | B32: 165310.2
A33: Grand Total | B33: 19801696
A39: Row Labels | B39: Sum of Total Profit
A40: Bakery | B40: 1004762.8
A41: Beverages | B41: 3785901.6
A42: Dairy | B42: 3049036.9
A43: Fruits & Vegetables | B43: 5015224.4
A44: Grains & Pulses | B44: 1667613.4
A45: Oils & Fats | B45: 1025057.3
A46: Seafood | B46: 3760727.1
A47: (blank) | B47: 160718.25
A48: Grand Total | B48: 19469042
